Workbook

Sheet Project Data
A1: Project Name | B1: AIlixir Intelligence
A3: Online team meeting | B3: https://tu-berlin.zoom-x.de/j/68161739941?pwd=Tz3duoAQeQHGWAsBNMexRqNxlnSPCI.1
A5: Production system (if any) | B5: ...
A6: Test system (if any) | B6: ...
A8: GitHub repository | B8: https://github.com/amosproj/amos2026ss03-ailixir-intelligence
A9: GitHub feature board | B9: https://github.com/orgs/amosproj/projects/99
A10: GitHub imp-squared backlog | B10: https://github.com/orgs/amosproj/projects/103/views/1
A12: Position of T-shirt logo | B12: Upper Torso Right Small
A13: Link to logo for black T-shirt | B13: https://www.shirtinator.com/s/w1QJzfDfTC-gGBjVmnCscg
A14: Link to logo for white T-shirt | B14: https://www.shirtinator.com/s/sMNil0MoQzmuNuc04Y6Ljw
A16: Additional materials | B16: ...
A18: Team maling list | B18: oss-amos-proj3@lists.fau.de

Sheet Project Team
A1: Last Name | B1: First Name | C1: GitHub User Name | D1: Email Address
A2: Brüggemann | B2: Jonas | C2: jonasbrue | D2: jonas.brueggemann@campus.tu-berlin.de
A3: Ebied | B3: Andrew | C3: andrewluka | D3: a.ebied@campus.tu-berlin.de
A4: Vinzens | B4: Hannes | C4: hannes-v | D4: hannes.vinzens@fau.de
A5: Ahmed | B5: Hasnat | C5: hasnatahmed331 | D5: hasnat.ahmed@fau.de
A6: Busse | B6: Tobias | C6: aseuc | D6: tobias.t.busse@fau.de
A7: Sandt | B7: Eloi | C7: eloinoel | D7: eloi.sandt@campus.tu-berlin.de
A8: Amer | B8: Hossam | C8: Hossam-Amer | D8: hossam.amer@fau.de
A9: Zeeshan | B9: Muhamad | C9: MuhammadZeeshan2 | D9: sharif.zeeshan@fau.de
A10: Haseeb | B10: Abdul | C10: AbdulHaseeb-SE | D10: abdul.ah.haseeb@fau.de
A11: Vogt | B11: Marcel | C11: VogtIndustries | D11: marcel.vogt@campus.tu-berlin.de

Sheet Role Assignments
C1: Product Owner
A2: # | B2: Meeting Day | C2: Review | D2: Planning | E2: Software Developer | F2: Release Manager | G2: Scrum Master | H2: Comment
A3: 1 | B3: 46127 | D3: Eloi | E3: Everyone else | F3: N/A | G3: COACH student
A4: 2 | B4: =B3+7 -> 46134 | C4: Eloi | D4: Tobias | E4: Everyone else | F4: Andrew Ebied | G4: COACH student
A5: 3 | B5: =B4+7 -> 46141 | C5: Tobias | D5: Eloi | E5: Everyone else | F5: Andrew Ebied | G5: COACH student
A6: 4 | B6: =B5+7 -> 46148 | C6: Eloi | D6: Tobias | E6: Everyone else | F6: Hasnat Ahmed | G6: COACH student
A7: 5 | B7: =B6+7 -> 46155 | C7: Tobias | D7: Eloi | E7: Everyone else | F7: Hossam Amer | G7: COACH student
A8: 6 | B8: =B7+7 -> 46162 | C8: Eloi | D8: Tobias | E8: ... | F8: Muhamad Zeeshan | G8: COACH student
A9: 7 | B9: =B8+7 -> 46169 | C9: Tobias | D9: Eloi | F9: Hannes Vinzens | G9: COACH student
A10: 8 | B10: =B9+7 -> 46176 | C10: Eloi | D10: Tobias | F10: Marcel Vogt | G10: COACH student
A11: 9 | B11: =B10+7 -> 46183 | C11: Tobias | D11: Eloi | F11: Abdul Haseeb | G11: COACH student
A12: 10 | B12: =B11+7 -> 46190 | C12: Eloi | D12: Tobias | F12: Hannes Vinzens | G12: COACH student
A13: 11 | B13: =B12+7 -> 46197 | C13: Tobias | D13: Eloi | F13: Hasnat Ahmed | G13: COACH student
A14: 12 | B14: =B13+7 -> 46204 | C14: Eloi | D14: Tobias | F14: Hossam Amer | G14: COACH student
A15: 13 | B15: =B14+7 -> 46211 | C15: Tobias | D15: Eloi | F15: Muhamad Zeeshan | G15: COACH student
A16: 14 | B16: =B15+7 -> 46218 | C16: Eloi | D16: / | F16: Abdul Haseeb | G16: COACH student | H16: Demo day!
A17: 15 | B17: =B16+7 -> 46225 | D17: / | G17: COACH student | H17: Retrospective
A19: Product owners, software developers, and Scurm Master are set and ideally don't change over time; the critical part is the Release Manager role you need to define here

Sheet Team Contract
A1: Goals | B1: Deliver MVP
B3: mutual and personal improvement
B4: deliver a maintainable prototype that can be potentially used as a starting point for the industry partner
A6: Meeting norms | B6: Meeting Should stick to deliverables.
B7: maybe once or twice per week. for each meeting, a document should be made that includes the points which we will go over. the document could be edited by anyone in case anyone has points they want to discuss in the meeting, although this might be particularly useful for POs.
B8: write an email in case you will be late/unable to attend team meetings
B9: be on time
B10: mute yourself in calls if you don't talk
B11: Protocol industry partner meetings
B12: Team Meeting starts at 12 (30 minutes earlier)
A13: Working norms
B14: deciding on a release manager should be part of the team meetings
B15: Would be cool if we could give an estimate of when we will be available to work, and if possible, also specify on which issues and till when we expect to be finished with them. in case of delays, i think they should be communicated as well so that the team gets a rough idea of when they could be done or if help is needed from other people
B16: SDs can self-assign issues at will; if that doesn't work out, issues will be assigned during team meetings
B17: Coding (style) guidelines, common AI agent setup, CI/CD linting/formating checks
B18: Documentation (how to run + code comments)
B19: Testing the written code/feature. All tests should pass before merging to main/master
B20: git flow strategy for working on code
B21: Definition of Done (DoD) A checklist of criteria (e.g. tests passed, code reviewed, documentation updated) that must be met before an issue is considered finished
B22: Definition of Ready (DoR); whether or not devs have enough capacity to take on an issue and finish it in time
B23: Pull Requests need to be reviewed and approved by at least one other developer
A24: Coordination norms
B25: Bigger decisions will be put to vote (ideally on slack)
B26: Work should be distributed with clear boundaries.
B27: use feature board actively and communicate with other people to coordinate work
A28: Communication norms
B31: replies within ~24h
B32: would also be cool if people communicate if they are unable to reply within 24h, with an estimate of when they will reply
B33: Communication with the industry partner over Slack
B34: it would also be nice to have dedicated communication channels for the team internally and with the industry partner. another dedicated channel for SDs as well
B35: agree on one main channel of communication: Slack
B36: Respect, active listening, tolerance
A37: Consideration norms
B38: Respect, Communicate Conflicts
B39: be kind and be cooperative
A41: Cont. improvement norms | B41: constructive criticism
B43: open feedback about things that could be improved
A44: Rewards
B46: eat ice cream together at the end of the course
A47: Sanctions
...

Sheet Product Goal
A1: Product Vision | B1: Project Mission
A3: AIlixir Intelligence transforms unstructured documents into connected, actionable knowledge. Users can upload or scan documents (e.g., medical reports, invoices), from which the system extracts domain-specific, meaningful data fields and organises them into a personalised knowledge base. An AI-powered voice/chat interface enables users to ask precise, context-aware questions and better understand their personal documents, as well as relationships and developments across their document history. At its core, the platform is designed to be domain-agnostic and configurable for a wide range of use cases. | B3: The mission of this project is to create an MVP that runs on mobile devices. Core functionality includes extracting structured information from uploaded documents, storing and organising it within a personal knowledge base, and enabling conversational querying using RAG with optional enrichment from external knowledge sources such as research papers. The system will demonstrate domain configurability using medical documents as the primary domain and finance as a secondary domain.

Sheet Product Glossary
A1: Term | B1: Definition
A2: AiLixir | B2: A mobile application that lets users capture or upload documents, extract structured knowledge from them, and ask an AI questions about the analysed content.
A3: User | B3: A person who uses AiLixir to manage documents, start knowledge extraction, view results, and interact with the AI.
A4: Account | B4: A user identity that stores private app data and enables access to personalised documents, chats, and extracted knowledge.
A5: Registration / Sign-up | B5: The process by which a new user creates an account, typically using email, password, and required personal details.
A6: Login | B6: The process by which an existing user proves their identity and gains access to private app screens and backend functionality.
A7: Authenticated User | B7: A user who has successfully logged in and is allowed to access private documents, protected screens, and authenticated backend APIs.
A8: Document | B8: A user-provided file or scan that can be stored, previewed, analysed, and used as the source for knowledge extraction.
A9: Captured Document | B9: A document created by taking a picture or scan with the smartphone camera and passing the result back to the app.
A10: Uploaded Document | B10: A document selected from the device file system or submitted from the camera that becomes available inside AiLixir.
A11: Document Preview | B11: A small visual representation of a selected document or document page before the user starts analysis or extraction.
A12: Document View | B12: The screen that lists the documents stored for the authenticated user and acts as the entry point to document actions.
... A54: OCR | B54: The process of converting text from scanned or photographed documents into machine-readable text before downstream extraction.

Sheet Sprint Goals
A1: Sprint # | B1: Sprint goal
A2: 1 | B2: None
A3: =A2+1 -> 2 | B3: None
A4: =A3+1 -> 3 | B4: None
A5: =A4+1 -> 4 | B5: Refine the knowledge graph pipeline, set up the database for persistent app storage, and implement a consistent layout.
A6: =A5+1 -> 5 | B6: Implement user authentication and backend integration for document uploads while building the frontend UI components and backend pipeline required for knowledge graph extraction.
A7: =A6+1 -> 6 | B7: Complete the end-to-end application by integrating frontend views with backend APIs, enabling knowledge graph extraction and providing visualisation options for extracted knowledge graphs.
A8: =A7+1 -> 7 | B8: Improve knowledge graph quality, introduce AI chat capabilities, and enhance the user experience with document handling and usability improvements.
A9: =A8+1 -> 8 | B9: Create a unified user knowledge graph and connect it to the chat system, enabling context-aware conversations and persistent chat management.
A10: =A9+1 -> 9 | B10: Enable an AI chat assistant experience through Knowledge Graph improvements, chat integration, and voice/camera capabilities.
A11: =A10+1 -> 10
A12: =A11+1 -> 11
A13: =A12+1 -> 12
A14: =A13+1 -> 13
A15: =A14+1 -> 14
A16: =A15+1 -> 15

Sheet Velocity Tracking
A1: Sprint # | B1: Story Points Realized | C1: Average
A2: 1 | C2: =AVERAGE(B2:B16) -> 22.5
A3: =A2+1 -> 2 | B3: 23 | C3: =AVERAGE(B2:B16) -> 22.5
A4: =A3+1 -> 3 | B4: 18 | C4: =AVERAGE(B2:B16) -> 22.5
A5: =A4+1 -> 4 | B5: 13 | C5: =AVERAGE(B2:B16) -> 22.5
A6: =A5+1 -> 5 | B6: 37 | C6: =AVERAGE(B2:B16) -> 22.5
A7: =A6+1 -> 6 | B7: 26 | C7: =AVERAGE(B2:B16) -> 22.5
A8: =A7+1 -> 7 | B8: 18 | C8: =AVERAGE(B2:B16) -> 22.5
A9: =A8+1 -> 8 | C9: =AVERAGE(B2:B16) -> 22.5
A10: =A9+1 -> 9 | C10: =AVERAGE(B2:B16) -> 22.5
A11: =A10+1 -> 10 | C11: =AVERAGE(B2:B16) -> 22.5
A12: =A11+1 -> 11 | C12: =AVERAGE(B2:B16) -> 22.5
A13: =A12+1 -> 12 | C13: =AVERAGE(B2:B16) -> 22.5
A14: =A13+1 -> 13 | C14: =AVERAGE(B2:B16) -> 22.5
B18: PLEASE CREATE THE VELOCITY CHART ON A NEW TAB USING THE DATA FROM THIS TAB

Sheet Velocity Chart

Sheet Mid-Project Release plan
A1: Sprint | B1: Goal | C1: Feature Name | D1: Est. size | E1: Est. remaining | F1: Real size | G1: Real remaining
A3: Release
A5: Total | D5: =sum(D8:D15) -> 121 | E5: =D5 -> 121
A7: Sprints
E8: Estimated burn-down | G8: Real burn-down
A9: 1 | B9: Establish the project foundation by completing initial research, defining the app direction, and setting up the frontend development environment. | D9: =sum(D18:D24) -> 0 | E9: =$D$5 -> 121 | F9: =sum(F18:F24) -> 0 | G9: =$D$5 -> 121
A10: =A9+1 -> 2 | B10: Deliver the first functional application prototype with document upload, authentication UI, architecture planning, and initial document analysis capabilities. | D10: =sum(D25:D30) -> 24 | E10: =E9-D9 -> 121 | F10: =sum(F25:F30) -> 23 | G10: =G9-F9 -> 121
A11: =A10+1 -> 3 | B11: Build the core document management UI, define the app navigation structure, and implement document capture using the camera while establishing the backend cloud infrastructure. | D11: =sum(D31:D35) -> 18 | E11: =E10-D10 -> 97 | F11: =sum(F31:F35) -> 18 | G11: =G10-F10 -> 98
A12: 4 | B12: Refine the knowledge graph pipeline, set up the database for persistent app storage, and implement a consistent layout. | D12: =sum(D36:D41) -> 18 | E12: =E11-D11 -> 79 | F12: =sum(F36:F41) -> 13 | G12: =G11-F11 -> 80
A13: 5 | B13: Implement user authentication and backend integration for document uploads while building the frontend UI components and backend pipeline required for knowledge graph extraction. | D13: =sum(D42:D50) -> 29 | E13: =E12-D12 -> 61 | F13: =sum(F42:F50) -> 37 | G13: =G12-F12 -> 67
A14: 6 | B14: Complete the end-to-end application by integrating frontend views with backend APIs, enabling knowledge graph extraction and providing visualisation options for extracted knowledge graphs. | D14: =sum(D51:D58) -> 32 | E14: =E13-D13 -> 32 | F14: =sum(F51:F58) -> 26 | G14: =G13-F13 -> 30
A16: Features
A18: =A9 -> 1 | B18: =B9 -> Establish the project foundation by completing initial research, defining the app direction, and setting up the frontend development environment. | C18: Setup documentation README.md
C19: Research which extraction tool do we use? (Document AI, OCR, OCR with Google AI)
C20: App Design Mockups / Wireframes / Moodboard
C21: Frontend Setup Development Environment for App
A25: =A10 -> 2 | B25: =B10 -> Deliver the first functional application prototype with document upload, authentication UI, architecture planning, and initial document analysis capabilities. | C25: Implement Document Analysis and Structured Data Output (JSON) | D25: 8 | F25: 8
C26: Deliverable: Software Architecture Design | D26: 8 | F26: 8
C27: Frontend: Github Actions CI/CD Pipeline | D27: 3 | F27: 3
C28: Interface includes a document upload screen | D28: 3 | F28: 2
C29: App Login Screen | D29: 2 | F29: 2
A31: =A11 -> 3 | B31: =B11 -> Build the core document management UI, define the app navigation structure, and implement document capture using the camera while establishing the backend cloud infrastructure. | C31: Frontend: Documents Overview | D31: 3 | F31: 5
C32: Capturing Documents using Camera/Scanning | D32: 5 | F32: 3
C33: App Navigation Tree | D33: 5 | F33: 5
C34: Setup GCP | D34: 5 | F34: 5
A36: 4 | B36: =B12 -> Refine the knowledge graph pipeline, set up the database for persistent app storage, and implement a consistent layout. | C36: Knowledge Graph Pipeline Refinement | D36: 8 | F36: 5
C37: Set up Database for App Persistent Storage | D37: 5 | F37: 5
C38: Consistent Layout | D38: 5 | F38: 3
A42: 5 | B42: =B13 -> Implement user authentication and backend integration for document uploads while building the frontend UI components and backend pipeline required for knowledge graph extraction. | C42: User Registration (Sign Up) View | D42: 1 | F42: 1
C43: User Registration (Functionality) | D43: 3 | F43: 2
C44: Login Authentication Process | D44: 5 | F44: 5
C45: Knowledge Graph Download Button | D45: 2 | F45: 3
C46: UI for Knowledge Extraction | D46: 2 | F46: 2
C47: Extracting Knowledge Graphs from Documents | D47: 8 | F47: 13
C48: Backend API: Documents | D48: 5 | F48: 8
C49: GCP Scheduling Extraction | D49: 3 | F49: 3
A51: 6 | B51: =B14 -> Complete the end-to-end application by integrating frontend views with backend APIs, enabling knowledge graph extraction and providing visualisation options for extracted knowledge graphs. | C51: Connecting Document Views to Backend | D51: 5 | F51: 3
C52: Connect Knowledge Extraction UI to Backend | D52: 5 | F52: 3
C53: Connecting Document Upload to Backend | D53: 3 | F53: 5
C54: Home Screen with Appropriate Navigation Options | D54: 3 | F54: 5
...

Sheet Burndown-Chart

Sheet Final Project Release plan
A1: Sprint | B1: Goal | C1: Feature Name | D1: Est. size | E1: Est. remaining | F1: Real size | G1: Real remaining
A3: Release
A5: Total | D5: =sum(D8:D16) -> 76 | E5: =D5 -> 76
A7: Sprints
E8: Estimated burn-down | G8: Real burn-down
A9: 7 | B9: Improve knowledge graph quality, introduce AI chat capabilities, and enhance the user experience with document handling and usability improvements. | D9: =sum(D19:D26) -> 31 | E9: =$D$5 -> 76 | F9: =sum(F19:F26) -> 18 | G9: =$D$5 -> 76
A10: =A9+1 -> 8 | B10: Create a unified user knowledge graph and connect it to the chat system, enabling context-aware conversations and persistent chat management. | D10: =sum(D27:D39) -> 45 | E10: =E9-D9 -> 45 | F10: =sum(F27:F39) -> 0 | G10: =G9-F9 -> 58
A11: =A10+1 -> 9 | B11: Enable an AI chat assistant experience through Knowledge Graph improvements, chat integration, and voice/camera capabilities. | D11: =sum(D40:D51) -> 0 | E11: =E10-D10 -> 0 | F11: =sum(F40:F51) -> 0 | G11: =G10-F10 -> 58
A12: =A11+1 -> 10 | B12: Integrate external knowledge sources such as research papers as AI chat contexts and visualise clickable sources in AI answers. | D12: =sum(D52:D61) -> 0 | E12: =E11-D11 -> 0 | F12: =sum(F52:F61) -> 0 | G12: =G11-F11 -> 58
A13: =A12+1 -> 11 | B13: Implement normal RAG chat as comparison to knowledge graph contexts in AI chats. | D13: =SUM(D62:D68) -> 0 | E13: =E12-D12 -> 0 | F13: =SUM(F62:F68) -> 0 | G13: =G12-F12 -> 58
A14: =A13+1 -> 12 | B14: Finalise features, documentation, bug fixes and polishing of UX. | D14: =SUM(D69:D74) -> 0 | E14: =E13-D13 -> 0 | F14: =SUM(F69:F74) -> 0 | G14: =G13-F13 -> 58
A15: =A14+1 -> 13 | B15: Buffer | D15: =SUM(D75:D81) -> 0 | E15: =E14-D14 -> 0 | F15: =SUM(F75:F81) -> 0 | G15: =G14-F14 -> 58
A17: Features
A19: =A9 -> 7 | B19: =B9 -> Improve knowledge graph quality, introduce AI chat capabilities, and enhance the user experience with document handling and usability improvements. | C19: Fix: Knowledge Graph Extraction API | D19: 3 | F19: not completed
C20: Knowledge Graph Refinement | D20: 5 | F20: 5
C21: API: LLM Chat Agent | D21: 5 | F21: not completed
C22: Chat Screen | D22: 5 | F22: 5
C23: Deleting Documents | D23: 3 | F23: 5
C24: Fix: Account Signup | D24: 3 | F24: 3
C25: Preview of Uploaded Documents | D25: 2 | F25: not completed
C26: Componentisation - Technical Debt - Beautify | D26: 5 | F26: not completed
A27: =A10 -> 8 | B27: =B10 -> Create a unified user knowledge graph and connect it to the chat system, enabling context-aware conversations and persistent chat management.
C28: API: LLM Chat Agent | D28: 5
C29: Fix: Knowledge Graph Extration API | D29: 3
C30: Knowledge Graph Context into LLM Prompts | D30: 8
C31: Deploy user knowledge graph in backend | D31: 3
C32: Creating Chats | D32: 1
C33: Persistent Chat History | D33: 5
C34: Preview of Uploaded Documents | D34: 2
C35: Chat Overview | D35: 3
C36: Chat Database | D36: 5
C37: Componentisation - Technical Debt - Beautify | D37: 5
C38: Combining all document sub-graphs into one | D38: 5
A40: =A11 -> 9 | B40: =B11 -> Enable an AI chat assistant experience through Knowledge Graph improvements, chat integration, and voice/camera capabilities. | C40: Fix: Retrieving the Knowledge Graph
C41: Ensure Knowledge Graph Correctness
C42: Chat Agent Memory
C43: API Test Environment
C44: Connect Chat Screen with LLM Chat Agent
C45: Dictate Chat Function
C46: Voice Chat Indicator
...

Sheet Burndown-Chart Final Project Re

Sheet Definition of Done
A1: # | B1: Feature Definition of Done | C1: Sprint Release Definition of Done | D1: Project Release Definition of Done
B2: The feature code has been reviewed and approved by at least one team member (e.g. pull request approved). | C2: The project builds, deploys, runs, and tests successfully in a clean environment (CI/CD pipeline passes). | D2: Application passes (user) testing across Android and iOS mobile devices.
B3: The feature code is merged into the main branch without breaking other functionality. | C3: Sprint release notes are written, summarising the modifications made during the sprint. | D3: User documentation is updated to provide instructions on how to build and use the application.
B4: The feature was manually tested and works as expected without critical bugs. | D4: Design documentation is updated to reflect the architecture and system design.
B5: Feature components are demo-ready.

Sheet Documentation
A1: Type | B1: Link / reference

Sheet Bill of Materials
A1: # | B1: Context | C1: Name | D1: Version | E1: License | F1: Comment
B2: frontend | C2: @langchain/react | D2: ^1.0.17 | E2: MIT
B3: frontend | C3: @langchain/core | D3: ^1.1.48 | E3: MIT
B4: frontend | C4: @assistant-ui/react-native | D4: ^0.1.21 | E4: MIT
B5: frontend | C5: @assistant-ui/react-langchain | D5: ^0.0.12 | E5: MIT
B6: frontend | C6: @assistant-ui/react | D6: ^0.14.14 | E6: MIT
B7: frontend | C7: @react-navigation/bottom-tabs | D7: ^7.15.5 | E7: MIT
B8: frontend | C8: @react-navigation/elements | D8: ^2.9.10 | E8: MIT
B9: frontend | C9: @react-navigation/native | D9: ^7.1.33 | E9: MIT
B10: frontend | C10: @tamagui/config | D10: ^2.0.0-rc.41 | E10: MIT
B11: frontend | C11: @tamagui/lucide-icons-2 | D11: ^2.0.0-rc.41 | E11: MIT
B12: frontend | C12: expo | D12: ~55.0.15 | E12: MIT
B13: frontend | C13: expo-constants | D13: ~55.0.14 | E13: MIT
... B66: backend | C66: python-multipart | D66: 0.0.27 | E66: Apache-2.0

Sheet Planning Poker
A1: ='Project Team'!A1 -> Last Name | B1: ='Project Team'!B1 -> First Name | C1: Value
A2: ='Project Team'!A2 -> Brüggemann | B2: ='Project Team'!B2 -> Jonas | C2: 0 | E2: =average(C2:C10) -> 0 | F2: =if(stdev(C2:C7) > 0,"NOK", "OK") -> OK
A3: Khan | B3: Muhamad | C3: 0
A4: ='Project Team'!A3 -> Ebied | B4: ='Project Team'!B3 -> Andrew
A5: ='Project Team'!A4 -> Vinzens | B5: ='Project Team'!B4 -> Hannes
A6: ='Project Team'!A5 -> Ahmed | B6: ='Project Team'!B5 -> Hasnat | E6: 0 | F6: No size
A7: Amer | B7: Hossam | E7: 1 | F7: Trivial size
A8: ='Project Team'!A7 -> Sandt | B8: ='Project Team'!B7 -> Eloi | E8: 2 | F8: Small size
A9: ='Project Team'!A6 -> Busse | B9: ='Project Team'!B6 -> Tobias | E9: 3 | F9: Medium size
A10: ='Project Team'!A9 -> Zeeshan | B10: ='Project Team'!B9 -> Muhamad | E10: 5 | F10: Large size
A11: ='Project Team'!A10 -> Haseeb | B11: ='Project Team'!B10 -> Abdul | E11: 8 | F11: Very large size
E12: 13 | F12: Too large (size)
A14: How to play planning poker
A16: 1. Everyone type their number into their value field, don't hit return yet
A17: 2. Someone, perhaps a product owner, count down 3.. 2.. 1..
A18: 3. Then, everyone hit return to submit their value
